<?xml version="1.0" encoding="utf-8"?>
<!-- This URDF was automatically created by SolidWorks to URDF Exporter! Originally created by Stephen Brawner (brawner@gmail.com) 
     Commit Version: 1.6.0-4-g7f85cfe  Build Version: 1.6.7995.38578
     For more information, please see http://wiki.ros.org/sw_urdf_exporter -->
<robot
  name="urdfdrone">
  <link
    name="origin">
    <inertial>
      <origin
        xyz="-0.00165109294138767 -9.15359281873607E-07 0.00622421349922927"
        rpy="0 0 0" />
      <mass
        value="0.0943248517999097" />
      <inertia
        ixx="5.8559454181496E-05"
        ixy="2.08845712215743E-09"
        ixz="-2.63097261266228E-07"
        iyy="6.03538258622224E-05"
        iyz="-1.26576301377632E-10"
        izz="0.000107624822835936" />
    </inertial>
    <visual>
      <origin
        xyz="0 0 0"
        rpy="0 0 0" />
      <geometry>
        <mesh
          filename="package://urdfdrone/meshes/origin.STL" />
      </geometry>
      <material
        name="">
        <color
          rgba="1 1 1 1" />
      </material>
    </visual>
    <collision>
      <origin
        xyz="0 0 0"
        rpy="0 0 0" />
      <geometry>
        <mesh
          filename="package://urdfdrone/meshes/origin.STL" />
      </geometry>
    </collision>
  </link>
  <link
    name="prop1">
    <inertial>
      <origin
        xyz="0 0 -0.000999999999999999"
        rpy="0 0 0" />
      <mass
        value="0.00693608313053282" />
      <inertia
        ixx="1.87898477712466E-06"
        ixy="-7.30502307325483E-38"
        ixz="-7.31814110008992E-40"
        iyy="1.87898477712466E-06"
        iyz="-3.59989002583076E-24"
        izz="3.75334549882896E-06" />
    </inertial>
    <visual>
      <origin
        xyz="0 0 0"
        rpy="0 0 0" />
      <geometry>
        <mesh
          filename="package://urdfdrone/meshes/prop1.STL" />
      </geometry>
      <material
        name="">
        <color
          rgba="0.792156862745098 0.819607843137255 0.933333333333333 1" />
      </material>
    </visual>
    <collision>
      <origin
        xyz="0 0 0"
        rpy="0 0 0" />
      <geometry>
        <mesh
          filename="package://urdfdrone/meshes/prop1.STL" />
      </geometry>
    </collision>
  </link>
  <joint
    name="prop1"
    type="continuous">
    <origin
      xyz="0.0397989898732233 -0.0397989898732233 0.0215"
      rpy="0 0 0" />
    <parent
      link="origin" />
    <child
      link="prop1" />
    <axis
      xyz="0 0 1" />
  </joint>
  <link
    name="prop4">
    <inertial>
      <origin
        xyz="0 0 -0.000999999999999999"
        rpy="0 0 0" />
      <mass
        value="0.00693608313053282" />
      <inertia
        ixx="1.87898477712466E-06"
        ixy="7.30502307325483E-38"
        ixz="-7.31814110008992E-40"
        iyy="1.87898477712466E-06"
        iyz="3.59989002583076E-24"
        izz="3.75334549882896E-06" />
    </inertial>
    <visual>
      <origin
        xyz="0 0 0"
        rpy="0 0 0" />
      <geometry>
        <mesh
          filename="package://urdfdrone/meshes/prop4.STL" />
      </geometry>
      <material
        name="">
        <color
          rgba="0.792156862745098 0.819607843137255 0.933333333333333 1" />
      </material>
    </visual>
    <collision>
      <origin
        xyz="0 0 0"
        rpy="0 0 0" />
      <geometry>
        <mesh
          filename="package://urdfdrone/meshes/prop4.STL" />
      </geometry>
    </collision>
  </link>
  <joint
    name="prop4"
    type="continuous">
    <origin
      xyz="0.0397989898732233 0.0397989898732233 0.0215"
      rpy="0 0 0" />
    <parent
      link="origin" />
    <child
      link="prop4" />
    <axis
      xyz="0 0 1" />
  </joint>
  <link
    name="prop3">
    <inertial>
      <origin
        xyz="0 0 -0.000494174107357031"
        rpy="0 0 0" />
      <mass
        value="0.00693608313053282" />
      <inertia
        ixx="1.87898477712466E-06"
        ixy="-7.30502307325483E-38"
        ixz="8.78176932010793E-40"
        iyy="1.87898477712466E-06"
        iyz="3.59989002583076E-24"
        izz="3.75334549882896E-06" />
    </inertial>
    <visual>
      <origin
        xyz="0 0 0"
        rpy="0 0 0" />
      <geometry>
        <mesh
          filename="package://urdfdrone/meshes/prop3.STL" />
      </geometry>
      <material
        name="">
        <color
          rgba="0.792156862745098 0.819607843137255 0.933333333333333 1" />
      </material>
    </visual>
    <collision>
      <origin
        xyz="0 0 0"
        rpy="0 0 0" />
      <geometry>
        <mesh
          filename="package://urdfdrone/meshes/prop3.STL" />
      </geometry>
    </collision>
  </link>
  <joint
    name="prop3"
    type="continuous">
    <origin
      xyz="-0.0397989898732233 0.0397989898732233 0.020994174107357"
      rpy="0 0 0" />
    <parent
      link="origin" />
    <child
      link="prop3" />
    <axis
      xyz="0 0 1" />
  </joint>
  <link
    name="prop2">
    <inertial>
      <origin
        xyz="0 0 0.000116422399766071"
        rpy="0 0 0" />
      <mass
        value="0.00693608313053282" />
      <inertia
        ixx="1.87898477712466E-06"
        ixy="7.30502307325483E-38"
        ixz="7.31814110008992E-40"
        iyy="1.87898477712466E-06"
        iyz="-3.59989002583076E-24"
        izz="3.75334549882896E-06" />
    </inertial>
    <visual>
      <origin
        xyz="0 0 0"
        rpy="0 0 0" />
      <geometry>
        <mesh
          filename="package://urdfdrone/meshes/prop2.STL" />
      </geometry>
      <material
        name="">
        <color
          rgba="0.792156862745098 0.819607843137255 0.933333333333333 1" />
      </material>
    </visual>
    <collision>
      <origin
        xyz="0 0 0"
        rpy="0 0 0" />
      <geometry>
        <mesh
          filename="package://urdfdrone/meshes/prop2.STL" />
      </geometry>
    </collision>
  </link>
  <joint
    name="prop2"
    type="continuous">
    <origin
      xyz="-0.0397989898732233 -0.0397989898732233 0.0203835776002339"
      rpy="0 0 0" />
    <parent
      link="origin" />
    <child
      link="prop2" />
    <axis
      xyz="0 0 1" />
  </joint>
</robot>